Workbook

Sheet Start Here
B2: DSA in 12 Weeks: NeetCode 150 Re-Solve Tracker
B3: By Nihar (@niihaaarrrr). Problem list: NeetCode 150 by NeetCode (neetcode.io). Arranged into 12 weeks for this video.
B5: First, make your own copy
B6: Google Sheets: File > Make a copy. Excel: download and save it. Only edit your copy.
B8: The rule this sheet is built on
B9: Solving a problem once is not learning it. A problem is yours only when you can solve it again on Day 30, on a blank page, without looking.
B11: The 6-step loop (do this for every problem)
B12: 1. Set a 20-minute timer. Close the solution tab. Write whatever idea comes first, even brute force.
B13: 2. Stuck after 20 minutes? Read the idea only (or watch the solution video), not the code. Close it and write the code yourself.
B14: 3. Write Time and Space complexity at the top of your code. Every problem, every time.
B15: 4. After Accepted, open the Discuss / Solutions tab. Find a second approach and compare the two.
B16: 5. Name the pattern and write a one-line trigger: when you see X in a question, think Y.
... B28: Example row (filled correctly)
B29: Problem | C29: Day 1 date | D29: Time / Space | E29: Pattern | F29: Trigger line | G29: Day 3 | H29: Day 7 | I29: Day 30
B30: Sort Colors (LC 75) | C30: 01-Nov-2026 | D30: O(n) time, O(1) space, one pass | E30: Two pointers, partition | F30: Only 2 or 3 kinds of values, arrange in place: use pointers | G30: Done | H30: Done | I30: Done
B32: Daily routine (2 to 3 hours)
B33: 1 to 2 new problems with the full 6-step loop.
B34: 30 minutes: every re-solve marked Re-solve due on the Tracker (filter the Status column).
B35: 30 minutes: core CS (OS, DBMS, SQL, OOP). From week 1, not after DSA.
B37: The 12 weeks
B38: Week 1: Arrays & Hashing + Two Pointers (14 problems)
B39: Week 2: Sliding Window + Stack (13 problems)
B40: Week 3: Binary Search + Intervals (13 problems)
B41: Week 4: Linked List (11 problems)
B42: Week 5: Trees (15 problems)
B43: Week 6: Heaps + Greedy (15 problems)
B44: Week 7: Backtracking + Tries (12 problems)
... B50: Week 12 has fewer new problems on purpose. Use the extra time to re-solve every problem not yet marked Mastered.

Sheet Progress
A1: Your progress
A2: Updates automatically from the Tracker tab. Mastered means the Day 30 re-solve is marked Done.
A4: Week | B4: Topic | C4: Problems | D4: Started | E4: Mastered (Day 30 done) | F4: % mastered | G4: Easy | H4: Medium | I4: Hard
A5: 1 | B5: Arrays & Hashing + Two Pointers | C5: =COUNTIF(Tracker!$A$2:$A$151,A5) -> 14 | D5: =COUNTIFS(Tracker!$A$2:$A$151,A5,Tracker!$H$2:$H$151,"<>") -> 0 | E5: =COUNTIFS(Tracker!$A$2:$A$151,A5,Tracker!$Q$2:$Q$151,"Done") -> 0 | F5: =IF(C5=0,0,E5/C5) -> 0 | G5: =COUNTIFS(Tracker!$A$2:$A$151,A5,Tracker!$E$2:$E$151,"Easy") -> 4 | H5: =COUNTIFS(Tracker!$A$2:$A$151,A5,Tracker!$E$2:$E$151,"Medium") -> 9 | I5: =COUNTIFS(Tracker!$A$2:$A$151,A5,Tracker!$E$2:$E$151,"Hard") -> 1
A6: 2 | B6: Sliding Window + Stack | C6: =COUNTIF(Tracker!$A$2:$A$151,A6) -> 13 | D6: =COUNTIFS(Tracker!$A$2:$A$151,A6,Tracker!$H$2:$H$151,"<>") -> 0 | E6: =COUNTIFS(Tracker!$A$2:$A$151,A6,Tracker!$Q$2:$Q$151,"Done") -> 0 | F6: =IF(C6=0,0,E6/C6) -> 0 | G6: =COUNTIFS(Tracker!$A$2:$A$151,A6,Tracker!$E$2:$E$151,"Easy") -> 2 | H6: =COUNTIFS(Tracker!$A$2:$A$151,A6,Tracker!$E$2:$E$151,"Medium") -> 8 | I6: =COUNTIFS(Tracker!$A$2:$A$151,A6,Tracker!$E$2:$E$151,"Hard") -> 3
A7: 3 | B7: Binary Search + Intervals | C7: =COUNTIF(Tracker!$A$2:$A$151,A7) -> 13 | D7: =COUNTIFS(Tracker!$A$2:$A$151,A7,Tracker!$H$2:$H$151,"<>") -> 0 | E7: =COUNTIFS(Tracker!$A$2:$A$151,A7,Tracker!$Q$2:$Q$151,"Done") -> 0 | F7: =IF(C7=0,0,E7/C7) -> 0 | G7: =COUNTIFS(Tracker!$A$2:$A$151,A7,Tracker!$E$2:$E$151,"Easy") -> 2 | H7: =COUNTIFS(Tracker!$A$2:$A$151,A7,Tracker!$E$2:$E$151,"Medium") -> 9 | I7: =COUNTIFS(Tracker!$A$2:$A$151,A7,Tracker!$E$2:$E$151,"Hard") -> 2
A8: 4 | B8: Linked List | C8: =COUNTIF(Tracker!$A$2:$A$151,A8) -> 11 | D8: =COUNTIFS(Tracker!$A$2:$A$151,A8,Tracker!$H$2:$H$151,"<>") -> 0 | E8: =COUNTIFS(Tracker!$A$2:$A$151,A8,Tracker!$Q$2:$Q$151,"Done") -> 0 | F8: =IF(C8=0,0,E8/C8) -> 0 | G8: =COUNTIFS(Tracker!$A$2:$A$151,A8,Tracker!$E$2:$E$151,"Easy") -> 3 | H8: =COUNTIFS(Tracker!$A$2:$A$151,A8,Tracker!$E$2:$E$151,"Medium") -> 6 | I8: =COUNTIFS(Tracker!$A$2:$A$151,A8,Tracker!$E$2:$E$151,"Hard") -> 2
A9: 5 | B9: Trees | C9: =COUNTIF(Tracker!$A$2:$A$151,A9) -> 15 | D9: =COUNTIFS(Tracker!$A$2:$A$151,A9,Tracker!$H$2:$H$151,"<>") -> 0 | E9: =COUNTIFS(Tracker!$A$2:$A$151,A9,Tracker!$Q$2:$Q$151,"Done") -> 0 | F9: =IF(C9=0,0,E9/C9) -> 0 | G9: =COUNTIFS(Tracker!$A$2:$A$151,A9,Tracker!$E$2:$E$151,"Easy") -> 6 | H9: =COUNTIFS(Tracker!$A$2:$A$151,A9,Tracker!$E$2:$E$151,"Medium") -> 7 | I9: =COUNTIFS(Tracker!$A$2:$A$151,A9,Tracker!$E$2:$E$151,"Hard") -> 2
A10: 6 | B10: Heaps + Greedy | C10: =COUNTIF(Tracker!$A$2:$A$151,A10) -> 15 | D10: =COUNTIFS(Tracker!$A$2:$A$151,A10,Tracker!$H$2:$H$151,"<>") -> 0 | E10: =COUNTIFS(Tracker!$A$2:$A$151,A10,Tracker!$Q$2:$Q$151,"Done") -> 0 | F10: =IF(C10=0,0,E10/C10) -> 0 | G10: =COUNTIFS(Tracker!$A$2:$A$151,A10,Tracker!$E$2:$E$151,"Easy") -> 2 | H10: =COUNTIFS(Tracker!$A$2:$A$151,A10,Tracker!$E$2:$E$151,"Medium") -> 12 | I10: =COUNTIFS(Tracker!$A$2:$A$151,A10,Tracker!$E$2:$E$151,"Hard") -> 1
A11: 7 | B11: Backtracking + Tries | C11: =COUNTIF(Tracker!$A$2:$A$151,A11) -> 12 | D11: =COUNTIFS(Tracker!$A$2:$A$151,A11,Tracker!$H$2:$H$151,"<>") -> 0 | E11: =COUNTIFS(Tracker!$A$2:$A$151,A11,Tracker!$Q$2:$Q$151,"Done") -> 0 | F11: =IF(C11=0,0,E11/C11) -> 0 | G11: =COUNTIFS(Tracker!$A$2:$A$151,A11,Tracker!$E$2:$E$151,"Easy") -> 0 | H11: =COUNTIFS(Tracker!$A$2:$A$151,A11,Tracker!$E$2:$E$151,"Medium") -> 10 | I11: =COUNTIFS(Tracker!$A$2:$A$151,A11,Tracker!$E$2:$E$151,"Hard") -> 2
A12: 8 | B12: Graphs | C12: =COUNTIF(Tracker!$A$2:$A$151,A12) -> 13 | D12: =COUNTIFS(Tracker!$A$2:$A$151,A12,Tracker!$H$2:$H$151,"<>") -> 0 | E12: =COUNTIFS(Tracker!$A$2:$A$151,A12,Tracker!$Q$2:$Q$151,"Done") -> 0 | F12: =IF(C12=0,0,E12/C12) -> 0 | G12: =COUNTIFS(Tracker!$A$2:$A$151,A12,Tracker!$E$2:$E$151,"Easy") -> 0 | H12: =COUNTIFS(Tracker!$A$2:$A$151,A12,Tracker!$E$2:$E$151,"Medium") -> 12 | I12: =COUNTIFS(Tracker!$A$2:$A$151,A12,Tracker!$E$2:$E$151,"Hard") -> 1
A13: 9 | B13: Advanced Graphs + Math & Geometry | C13: =COUNTIF(Tracker!$A$2:$A$151,A13) -> 14 | D13: =COUNTIFS(Tracker!$A$2:$A$151,A13,Tracker!$H$2:$H$151,"<>") -> 0 | E13: =COUNTIFS(Tracker!$A$2:$A$151,A13,Tracker!$Q$2:$Q$151,"Done") -> 0 | F13: =IF(C13=0,0,E13/C13) -> 0 | G13: =COUNTIFS(Tracker!$A$2:$A$151,A13,Tracker!$E$2:$E$151,"Easy") -> 2 | H13: =COUNTIFS(Tracker!$A$2:$A$151,A13,Tracker!$E$2:$E$151,"Medium") -> 9 | I13: =COUNTIFS(Tracker!$A$2:$A$151,A13,Tracker!$E$2:$E$151,"Hard") -> 3
A14: 10 | B14: 1-D Dynamic Programming | C14: =COUNTIF(Tracker!$A$2:$A$151,A14) -> 12 | D14: =COUNTIFS(Tracker!$A$2:$A$151,A14,Tracker!$H$2:$H$151,"<>") -> 0 | E14: =COUNTIFS(Tracker!$A$2:$A$151,A14,Tracker!$Q$2:$Q$151,"Done") -> 0 | F14: =IF(C14=0,0,E14/C14) -> 0 | G14: =COUNTIFS(Tracker!$A$2:$A$151,A14,Tracker!$E$2:$E$151,"Easy") -> 2 | H14: =COUNTIFS(Tracker!$A$2:$A$151,A14,Tracker!$E$2:$E$151,"Medium") -> 10 | I14: =COUNTIFS(Tracker!$A$2:$A$151,A14,Tracker!$E$2:$E$151,"Hard") -> 0
A15: 11 | B15: 2-D Dynamic Programming | C15: =COUNTIF(Tracker!$A$2:$A$151,A15) -> 11 | D15: =COUNTIFS(Tracker!$A$2:$A$151,A15,Tracker!$H$2:$H$151,"<>") -> 0 | E15: =COUNTIFS(Tracker!$A$2:$A$151,A15,Tracker!$Q$2:$Q$151,"Done") -> 0 | F15: =IF(C15=0,0,E15/C15) -> 0 | G15: =COUNTIFS(Tracker!$A$2:$A$151,A15,Tracker!$E$2:$E$151,"Easy") -> 0 | H15: =COUNTIFS(Tracker!$A$2:$A$151,A15,Tracker!$E$2:$E$151,"Medium") -> 7 | I15: =COUNTIFS(Tracker!$A$2:$A$151,A15,Tracker!$E$2:$E$151,"Hard") -> 4
A16: 12 | B16: Bit Manipulation + Full Revision | C16: =COUNTIF(Tracker!$A$2:$A$151,A16) -> 7 | D16: =COUNTIFS(Tracker!$A$2:$A$151,A16,Tracker!$H$2:$H$151,"<>") -> 0 | E16: =COUNTIFS(Tracker!$A$2:$A$151,A16,Tracker!$Q$2:$Q$151,"Done") -> 0 | F16: =IF(C16=0,0,E16/C16) -> 0 | G16: =COUNTIFS(Tracker!$A$2:$A$151,A16,Tracker!$E$2:$E$151,"Easy") -> 5 | H16: =COUNTIFS(Tracker!$A$2:$A$151,A16,Tracker!$E$2:$E$151,"Medium") -> 2 | I16: =COUNTIFS(Tracker!$A$2:$A$151,A16,Tracker!$E$2:$E$151,"Hard") -> 0
B17: Total | C17: =SUM(C5:C16) -> 150 | D17: =SUM(D5:D16) -> 0 | E17: =SUM(E5:E16) -> 0 | F17: =IF(C17=0,0,E17/C17) -> 0 | G17: =SUM(G5:G16) -> 28 | H17: =SUM(H5:H16) -> 101 | I17: =SUM(I5:I16) -> 21
B19: Re-solves due today | C19: =COUNTIF(Tracker!$S$2:$S$151,"Re-solve due") -> 0
B20: Marked Redo (restart these) | C20: =COUNTIF(Tracker!$S$2:$S$151,"Redo") -> 0

Sheet Tracker
A1: Week | B1: Topic | C1: # | D1: Problem (opens LeetCode) | E1: Difficulty | F1: Free link (premium only) | G1: Solution video (only after 20 min) | H1: Day 1 date | I1: Time / Space | J1: Pattern | K1: Trigger line | L1: Day 3 due | M1: Day 3 | N1: Day 7 due | O1: Day 7 | P1: Day 30 due | Q1: Day 30 | R1: Next re-solve | S1: Status
A2: 1 | B2: Arrays & Hashing | C2: 217 | D2: Contains Duplicate | E2: Easy | G2: Watch | L2: =IF(H2="","",H2+2) | N2: =IF(H2="","",H2+6) | P2: =IF(H2="","",H2+29) | R2: =IF(H2="","",IF(Q2="Done","Mastered",IF(M2<>"Done",L2,IF(O2<>"Done",N2,P2)))) | S2: =IF(H2="","Not started",IF(Q2="Done","Mastered",IF(OR(M2="Redo",O2="Redo",Q2="Redo"),"Redo",IF(R2<=TODAY(),"Re-solve due","In progress")))) -> Not started
A3: 1 | B3: Arrays & Hashing | C3: 242 | D3: Valid Anagram | E3: Easy | G3: Watch | L3: =IF(H3="","",H3+2) | N3: =IF(H3="","",H3+6) | P3: =IF(H3="","",H3+29) | R3: =IF(H3="","",IF(Q3="Done","Mastered",IF(M3<>"Done",L3,IF(O3<>"Done",N3,P3)))) | S3: =IF(H3="","Not started",IF(Q3="Done","Mastered",IF(OR(M3="Redo",O3="Redo",Q3="Redo"),"Redo",IF(R3<=TODAY(),"Re-solve due","In progress")))) -> Not started
A4: 1 | B4: Arrays & Hashing | C4: 1 | D4: Two Sum | E4: Easy | G4: Watch | L4: =IF(H4="","",H4+2) | N4: =IF(H4="","",H4+6) | P4: =IF(H4="","",H4+29) | R4: =IF(H4="","",IF(Q4="Done","Mastered",IF(M4<>"Done",L4,IF(O4<>"Done",N4,P4)))) | S4: =IF(H4="","Not started",IF(Q4="Done","Mastered",IF(OR(M4="Redo",O4="Redo",Q4="Redo"),"Redo",IF(R4<=TODAY(),"Re-solve due","In progress")))) -> Not started
A5: 1 | B5: Arrays & Hashing | C5: 49 | D5: Group Anagrams | E5: Medium | G5: Watch | L5: =IF(H5="","",H5+2) | N5: =IF(H5="","",H5+6) | P5: =IF(H5="","",H5+29) | R5: =IF(H5="","",IF(Q5="Done","Mastered",IF(M5<>"Done",L5,IF(O5<>"Done",N5,P5)))) | S5: =IF(H5="","Not started",IF(Q5="Done","Mastered",IF(OR(M5="Redo",O5="Redo",Q5="Redo"),"Redo",IF(R5<=TODAY(),"Re-solve due","In progress")))) -> Not started
A6: 1 | B6: Arrays & Hashing | C6: 347 | D6: Top K Frequent Elements | E6: Medium | G6: Watch | L6: =IF(H6="","",H6+2) | N6: =IF(H6="","",H6+6) | P6: =IF(H6="","",H6+29) | R6: =IF(H6="","",IF(Q6="Done","Mastered",IF(M6<>"Done",L6,IF(O6<>"Done",N6,P6)))) | S6: =IF(H6="","Not started",IF(Q6="Done","Mastered",IF(OR(M6="Redo",O6="Redo",Q6="Redo"),"Redo",IF(R6<=TODAY(),"Re-solve due","In progress")))) -> Not started
A7: 1 | B7: Arrays & Hashing | C7: 238 | D7: Product of Array Except Self | E7: Medium | G7: Watch | L7: =IF(H7="","",H7+2) | N7: =IF(H7="","",H7+6) | P7: =IF(H7="","",H7+29) | R7: =IF(H7="","",IF(Q7="Done","Mastered",IF(M7<>"Done",L7,IF(O7<>"Done",N7,P7)))) | S7: =IF(H7="","Not started",IF(Q7="Done","Mastered",IF(OR(M7="Redo",O7="Redo",Q7="Redo"),"Redo",IF(R7<=TODAY(),"Re-solve due","In progress")))) -> Not started
A8: 1 | B8: Arrays & Hashing | C8: 36 | D8: Valid Sudoku | E8: Medium | G8: Watch | L8: =IF(H8="","",H8+2) | N8: =IF(H8="","",H8+6) | P8: =IF(H8="","",H8+29) | R8: =IF(H8="","",IF(Q8="Done","Mastered",IF(M8<>"Done",L8,IF(O8<>"Done",N8,P8)))) | S8: =IF(H8="","Not started",IF(Q8="Done","Mastered",IF(OR(M8="Redo",O8="Redo",Q8="Redo"),"Redo",IF(R8<=TODAY(),"Re-solve due","In progress")))) -> Not started
A9: 1 | B9: Arrays & Hashing | C9: 271 | D9: Encode and Decode Strings | E9: Medium | F9: Free version | G9: Watch | L9: =IF(H9="","",H9+2) | N9: =IF(H9="","",H9+6) | P9: =IF(H9="","",H9+29) | R9: =IF(H9="","",IF(Q9="Done","Mastered",IF(M9<>"Done",L9,IF(O9<>"Done",N9,P9)))) | S9: =IF(H9="","Not started",IF(Q9="Done","Mastered",IF(OR(M9="Redo",O9="Redo",Q9="Redo"),"Redo",IF(R9<=TODAY(),"Re-solve due","In progress")))) -> Not started
A10: 1 | B10: Arrays & Hashing | C10: 128 | D10: Longest Consecutive Sequence | E10: Medium | G10: Watch | L10: =IF(H10="","",H10+2) | N10: =IF(H10="","",H10+6) | P10: =IF(H10="","",H10+29) | R10: =IF(H10="","",IF(Q10="Done","Mastered",IF(M10<>"Done",L10,IF(O10<>"Done",N10,P10)))) | S10: =IF(H10="","Not started",IF(Q10="Done","Mastered",IF(OR(M10="Redo",O10="Redo",Q10="Redo"),"Redo",IF(R10<=TODAY(),"Re-solve due","In progress")))) -> Not started
A11: 1 | B11: Two Pointers | C11: 125 | D11: Valid Palindrome | E11: Easy | G11: Watch | L11: =IF(H11="","",H11+2) | N11: =IF(H11="","",H11+6) | P11: =IF(H11="","",H11+29) | R11: =IF(H11="","",IF(Q11="Done","Mastered",IF(M11<>"Done",L11,IF(O11<>"Done",N11,P11)))) | S11: =IF(H11="","Not started",IF(Q11="Done","Mastered",IF(OR(M11="Redo",O11="Redo",Q11="Redo"),"Redo",IF(R11<=TODAY(),"Re-solve due","In progress")))) -> Not started
A12: 1 | B12: Two Pointers | C12: 167 | D12: Two Sum II (Input Array Is Sorted) | E12: Medium | G12: Watch | L12: =IF(H12="","",H12+2) | N12: =IF(H12="","",H12+6) | P12: =IF(H12="","",H12+29) | R12: =IF(H12="","",IF(Q12="Done","Mastered",IF(M12<>"Done",L12,IF(O12<>"Done",N12,P12)))) | S12: =IF(H12="","Not started",IF(Q12="Done","Mastered",IF(OR(M12="Redo",O12="Redo",Q12="Redo"),"Redo",IF(R12<=TODAY(),"Re-solve due","In progress")))) -> Not started
A13: 1 | B13: Two Pointers | C13: 15 | D13: 3Sum | E13: Medium | G13: Watch | L13: =IF(H13="","",H13+2) | N13: =IF(H13="","",H13+6) | P13: =IF(H13="","",H13+29) | R13: =IF(H13="","",IF(Q13="Done","Mastered",IF(M13<>"Done",L13,IF(O13<>"Done",N13,P13)))) | S13: =IF(H13="","Not started",IF(Q13="Done","Mastered",IF(OR(M13="Redo",O13="Redo",Q13="Redo"),"Redo",IF(R13<=TODAY(),"Re-solve due","In progress")))) -> Not started
A14: 1 | B14: Two Pointers | C14: 11 | D14: Container With Most Water | E14: Medium | G14: Watch | L14: =IF(H14="","",H14+2) | N14: =IF(H14="","",H14+6) | P14: =IF(H14="","",H14+29) | R14: =IF(H14="","",IF(Q14="Done","Mastered",IF(M14<>"Done",L14,IF(O14<>"Done",N14,P14)))) | S14: =IF(H14="","Not started",IF(Q14="Done","Mastered",IF(OR(M14="Redo",O14="Redo",Q14="Redo"),"Redo",IF(R14<=TODAY(),"Re-solve due","In progress")))) -> Not started
A15: 1 | B15: Two Pointers | C15: 42 | D15: Trapping Rain Water | E15: Hard | G15: Watch | L15: =IF(H15="","",H15+2) | N15: =IF(H15="","",H15+6) | P15: =IF(H15="","",H15+29) | R15: =IF(H15="","",IF(Q15="Done","Mastered",IF(M15<>"Done",L15,IF(O15<>"Done",N15,P15)))) | S15: =IF(H15="","Not started",IF(Q15="Done","Mastered",IF(OR(M15="Redo",O15="Redo",Q15="Redo"),"Redo",IF(R15<=TODAY(),"Re-solve due","In progress")))) -> Not started
A16: 2 | B16: Sliding Window | C16: 121 | D16: Best Time to Buy And Sell Stock | E16: Easy | G16: Watch | L16: =IF(H16="","",H16+2) | N16: =IF(H16="","",H16+6) | P16: =IF(H16="","",H16+29) | R16: =IF(H16="","",IF(Q16="Done","Mastered",IF(M16<>"Done",L16,IF(O16<>"Done",N16,P16)))) | S16: =IF(H16="","Not started",IF(Q16="Done","Mastered",IF(OR(M16="Redo",O16="Redo",Q16="Redo"),"Redo",IF(R16<=TODAY(),"Re-solve due","In progress")))) -> Not started
A17: 2 | B17: Sliding Window | C17: 3 | D17: Longest Substring Without Repeating Characters | E17: Medium | G17: Watch | L17: =IF(H17="","",H17+2) | N17: =IF(H17="","",H17+6) | P17: =IF(H17="","",H17+29) | R17: =IF(H17="","",IF(Q17="Done","Mastered",IF(M17<>"Done",L17,IF(O17<>"Done",N17,P17)))) | S17: =IF(H17="","Not started",IF(Q17="Done","Mastered",IF(OR(M17="Redo",O17="Redo",Q17="Redo"),"Redo",IF(R17<=TODAY(),"Re-solve due","In progress")))) -> Not started
A18: 2 | B18: Sliding Window | C18: 424 | D18: Longest Repeating Character Replacement | E18: Medium | G18: Watch | L18: =IF(H18="","",H18+2) | N18: =IF(H18="","",H18+6) | P18: =IF(H18="","",H18+29) | R18: =IF(H18="","",IF(Q18="Done","Mastered",IF(M18<>"Done",L18,IF(O18<>"Done",N18,P18)))) | S18: =IF(H18="","Not started",IF(Q18="Done","Mastered",IF(OR(M18="Redo",O18="Redo",Q18="Redo"),"Redo",IF(R18<=TODAY(),"Re-solve due","In progress")))) -> Not started
A19: 2 | B19: Sliding Window | C19: 567 | D19: Permutation In String | E19: Medium | G19: Watch | L19: =IF(H19="","",H19+2) | N19: =IF(H19="","",H19+6) | P19: =IF(H19="","",H19+29) | R19: =IF(H19="","",IF(Q19="Done","Mastered",IF(M19<>"Done",L19,IF(O19<>"Done",N19,P19)))) | S19: =IF(H19="","Not started",IF(Q19="Done","Mastered",IF(OR(M19="Redo",O19="Redo",Q19="Redo"),"Redo",IF(R19<=TODAY(),"Re-solve due","In progress")))) -> Not started
A20: 2 | B20: Sliding Window | C20: 76 | D20: Minimum Window Substring | E20: Hard | G20: Watch | L20: =IF(H20="","",H20+2) | N20: =IF(H20="","",H20+6) | P20: =IF(H20="","",H20+29) | R20: =IF(H20="","",IF(Q20="Done","Mastered",IF(M20<>"Done",L20,IF(O20<>"Done",N20,P20)))) | S20: =IF(H20="","Not started",IF(Q20="Done","Mastered",IF(OR(M20="Redo",O20="Redo",Q20="Redo"),"Redo",IF(R20<=TODAY(),"Re-solve due","In progress")))) -> Not started
A21: 2 | B21: Sliding Window | C21: 239 | D21: Sliding Window Maximum | E21: Hard | G21: Watch | L21: =IF(H21="","",H21+2) | N21: =IF(H21="","",H21+6) | P21: =IF(H21="","",H21+29) | R21: =IF(H21="","",IF(Q21="Done","Mastered",IF(M21<>"Done",L21,IF(O21<>"Done",N21,P21)))) | S21: =IF(H21="","Not started",IF(Q21="Done","Mastered",IF(OR(M21="Redo",O21="Redo",Q21="Redo"),"Redo",IF(R21<=TODAY(),"Re-solve due","In progress")))) -> Not started
... A35: 3 | B35: Binary Search | C35: 4 | D35: Median of Two Sorted Arrays | E35: Hard | G35: Watch | L35: =IF(H35="","",H35+2) | N35: =IF(H35="","",H35+6) | P35: =IF(H35="","",H35+29) | R35: =IF(H35="","",IF(Q35="Done","Mastered",IF(M35<>"Done",L35,IF(O35<>"Done",N35,P35)))) | S35: =IF(H35="","Not started",IF(Q35="Done","Mastered",IF(OR(M35="Redo",O35="Redo",Q35="Redo"),"Redo",IF(R35<=TODAY(),"Re-solve due","In progress")))) -> Not started
A36: 3 | B36: Intervals | C36: 252 | D36: Meeting Rooms | E36: Easy | F36: Free version | G36: Watch | L36: =IF(H36="","",H36+2) | N36: =IF(H36="","",H36+6) | P36: =IF(H36="","",H36+29) | R36: =IF(H36="","",IF(Q36="Done","Mastered",IF(M36<>"Done",L36,IF(O36<>"Done",N36,P36)))) | S36: =IF(H36="","Not started",IF(Q36="Done","Mastered",IF(OR(M36="Redo",O36="Redo",Q36="Redo"),"Redo",IF(R36<=TODAY(),"Re-solve due","In progress")))) -> Not started
A37: 3 | B37: Intervals | C37: 57 | D37: Insert Interval | E37: Medium | G37: Watch | L37: =IF(H37="","",H37+2) | N37: =IF(H37="","",H37+6) | P37: =IF(H37="","",H37+29) | R37: =IF(H37="","",IF(Q37="Done","Mastered",IF(M37<>"Done",L37,IF(O37<>"Done",N37,P37)))) | S37: =IF(H37="","Not started",IF(Q37="Done","Mastered",IF(OR(M37="Redo",O37="Redo",Q37="Redo"),"Redo",IF(R37<=TODAY(),"Re-solve due","In progress")))) -> Not started
A38: 3 | B38: Intervals | C38: 56 | D38: Merge Intervals | E38: Medium | G38: Watch | L38: =IF(H38="","",H38+2) | N38: =IF(H38="","",H38+6) | P38: =IF(H38="","",H38+29) | R38: =IF(H38="","",IF(Q38="Done","Mastered",IF(M38<>"Done",L38,IF(O38<>"Done",N38,P38)))) | S38: =IF(H38="","Not started",IF(Q38="Done","Mastered",IF(OR(M38="Redo",O38="Redo",Q38="Redo"),"Redo",IF(R38<=TODAY(),"Re-solve due","In progress")))) -> Not started
A39: 3 | B39: Intervals | C39: 435 | D39: Non-overlapping Intervals | E39: Medium | G39: Watch | L39: =IF(H39="","",H39+2) | N39: =IF(H39="","",H39+6) | P39: =IF(H39="","",H39+29) | R39: =IF(H39="","",IF(Q39="Done","Mastered",IF(M39<>"Done",L39,IF(O39<>"Done",N39,P39)))) | S39: =IF(H39="","Not started",IF(Q39="Done","Mastered",IF(OR(M39="Redo",O39="Redo",Q39="Redo"),"Redo",IF(R39<=TODAY(),"Re-solve due","In progress")))) -> Not started
A40: 3 | B40: Intervals | C40: 253 | D40: Meeting Rooms II | E40: Medium | F40: Free version | G40: Watch | L40: =IF(H40="","",H40+2) | N40: =IF(H40="","",H40+6) | P40: =IF(H40="","",H40+29) | R40: =IF(H40="","",IF(Q40="Done","Mastered",IF(M40<>"Done",L40,IF(O40<>"Done",N40,P40)))) | S40: =IF(H40="","Not started",IF(Q40="Done","Mastered",IF(OR(M40="Redo",O40="Redo",Q40="Redo"),"Redo",IF(R40<=TODAY(),"Re-solve due","In progress")))) -> Not started
A41: 3 | B41: Intervals | C41: 1851 | D41: Minimum Interval to Include Each Query | E41: Hard | G41: Watch | L41: =IF(H41="","",H41+2) | N41: =IF(H41="","",H41+6) | P41: =IF(H41="","",H41+29) | R41: =IF(H41="","",IF(Q41="Done","Mastered",IF(M41<>"Done",L41,IF(O41<>"Done",N41,P41)))) | S41: =IF(H41="","Not started",IF(Q41="Done","Mastered",IF(OR(M41="Redo",O41="Redo",Q41="Redo"),"Redo",IF(R41<=TODAY(),"Re-solve due","In progress")))) -> Not started
A42: 4 | B42: Linked List | C42: 206 | D42: Reverse Linked List | E42: Easy | G42: Watch | L42: =IF(H42="","",H42+2) | N42: =IF(H42="","",H42+6) | P42: =IF(H42="","",H42+29) | R42: =IF(H42="","",IF(Q42="Done","Mastered",IF(M42<>"Done",L42,IF(O42<>"Done",N42,P42)))) | S42: =IF(H42="","Not started",IF(Q42="Done","Mastered",IF(OR(M42="Redo",O42="Redo",Q42="Redo"),"Redo",IF(R42<=TODAY(),"Re-solve due","In progress")))) -> Not started
A43: 4 | B43: Linked List | C43: 21 | D43: Merge Two Sorted Lists | E43: Easy | G43: Watch | L43: =IF(H43="","",H43+2) | N43: =IF(H43="","",H43+6) | P43: =IF(H43="","",H43+29) | R43: =IF(H43="","",IF(Q43="Done","Mastered",IF(M43<>"Done",L43,IF(O43<>"Done",N43,P43)))) | S43: =IF(H43="","Not started",IF(Q43="Done","Mastered",IF(OR(M43="Redo",O43="Redo",Q43="Redo"),"Redo",IF(R43<=TODAY(),"Re-solve due","In progress")))) -> Not started
A44: 4 | B44: Linked List | C44: 141 | D44: Linked List Cycle | E44: Easy | G44: Watch | L44: =IF(H44="","",H44+2) | N44: =IF(H44="","",H44+6) | P44: =IF(H44="","",H44+29) | R44: =IF(H44="","",IF(Q44="Done","Mastered",IF(M44<>"Done",L44,IF(O44<>"Done",N44,P44)))) | S44: =IF(H44="","Not started",IF(Q44="Done","Mastered",IF(OR(M44="Redo",O44="Redo",Q44="Redo"),"Redo",IF(R44<=TODAY(),"Re-solve due","In progress")))) -> Not started
A45: 4 | B45: Linked List | C45: 143 | D45: Reorder List | E45: Medium | G45: Watch | L45: =IF(H45="","",H45+2) | N45: =IF(H45="","",H45+6) | P45: =IF(H45="","",H45+29) | R45: =IF(H45="","",IF(Q45="Done","Mastered",IF(M45<>"Done",L45,IF(O45<>"Done",N45,P45)))) | S45: =IF(H45="","Not started",IF(Q45="Done","Mastered",IF(OR(M45="Redo",O45="Redo",Q45="Redo"),"Redo",IF(R45<=TODAY(),"Re-solve due","In progress")))) -> Not started
A46: 4 | B46: Linked List | C46: 19 | D46: Remove Nth Node From End of List | E46: Medium | G46: Watch | L46: =IF(H46="","",H46+2) | N46: =IF(H46="","",H46+6) | P46: =IF(H46="","",H46+29) | R46: =IF(H46="","",IF(Q46="Done","Mastered",IF(M46<>"Done",L46,IF(O46<>"Done",N46,P46)))) | S46: =IF(H46="","Not started",IF(Q46="Done","Mastered",IF(OR(M46="Redo",O46="Redo",Q46="Redo"),"Redo",IF(R46<=TODAY(),"Re-solve due","In progress")))) -> Not started
A47: 4 | B47: Linked List | C47: 138 | D47: Copy List With Random Pointer | E47: Medium | G47: Watch | L47: =IF(H47="","",H47+2) | N47: =IF(H47="","",H47+6) | P47: =IF(H47="","",H47+29) | R47: =IF(H47="","",IF(Q47="Done","Mastered",IF(M47<>"Done",L47,IF(O47<>"Done",N47,P47)))) | S47: =IF(H47="","Not started",IF(Q47="Done","Mastered",IF(OR(M47="Redo",O47="Redo",Q47="Redo"),"Redo",IF(R47<=TODAY(),"Re-solve due","In progress")))) -> Not started
A48: 4 | B48: Linked List | C48: 2 | D48: Add Two Numbers | E48: Medium | G48: Watch | L48: =IF(H48="","",H48+2) | N48: =IF(H48="","",H48+6) | P48: =IF(H48="","",H48+29) | R48: =IF(H48="","",IF(Q48="Done","Mastered",IF(M48<>"Done",L48,IF(O48<>"Done",N48,P48)))) | S48: =IF(H48="","Not started",IF(Q48="Done","Mastered",IF(OR(M48="Redo",O48="Redo",Q48="Redo"),"Redo",IF(R48<=TODAY(),"Re-solve due","In progress")))) -> Not started
A49: 4 | B49: Linked List | C49: 287 | D49: Find The Duplicate Number | E49: Medium | G49: Watch | L49: =IF(H49="","",H49+2) | N49: =IF(H49="","",H49+6) | P49: =IF(H49="","",H49+29) | R49: =IF(H49="","",IF(Q49="Done","Mastered",IF(M49<>"Done",L49,IF(O49<>"Done",N49,P49)))) | S49: =IF(H49="","Not started",IF(Q49="Done","Mastered",IF(OR(M49="Redo",O49="Redo",Q49="Redo"),"Redo",IF(R49<=TODAY(),"Re-solve due","In progress")))) -> Not started
A50: 4 | B50: Linked List | C50: 146 | D50: LRU Cache | E50: Medium | G50: Watch | L50: =IF(H50="","",H50+2) | N50: =IF(H50="","",H50+6) | P50: =IF(H50="","",H50+29) | R50: =IF(H50="","",IF(Q50="Done","Mastered",IF(M50<>"Done",L50,IF(O50<>"Done",N50,P50)))) | S50: =IF(H50="","Not started",IF(Q50="Done","Mastered",IF(OR(M50="Redo",O50="Redo",Q50="Redo"),"Redo",IF(R50<=TODAY(),"Re-solve due","In progress")))) -> Not started
A51: 4 | B51: Linked List | C51: 23 | D51: Merge k Sorted Lists | E51: Hard | G51: Watch | L51: =IF(H51="","",H51+2) | N51: =IF(H51="","",H51+6) | P51: =IF(H51="","",H51+29) | R51: =IF(H51="","",IF(Q51="Done","Mastered",IF(M51<>"Done",L51,IF(O51<>"Done",N51,P51)))) | S51: =IF(H51="","Not started",IF(Q51="Done","Mastered",IF(OR(M51="Redo",O51="Redo",Q51="Redo"),"Redo",IF(R51<=TODAY(),"Re-solve due","In progress")))) -> Not started
A52: 4 | B52: Linked List | C52: 25 | D52: Reverse Nodes in k-Group | E52: Hard | G52: Watch | L52: =IF(H52="","",H52+2) | N52: =IF(H52="","",H52+6) | P52: =IF(H52="","",H52+29) | R52: =IF(H52="","",IF(Q52="Done","Mastered",IF(M52<>"Done",L52,IF(O52<>"Done",N52,P52)))) | S52: =IF(H52="","Not started",IF(Q52="Done","Mastered",IF(OR(M52="Redo",O52="Redo",Q52="Redo"),"Redo",IF(R52<=TODAY(),"Re-solve due","In progress")))) -> Not started
... A100: 8 | B100: Graphs | C100: 994 | D100: Rotting Oranges | E100: Medium | G100: Watch | L100: =IF(H100="","",H100+2) | N100: =IF(H100="","",H100+6) | P100: =IF(H100="","",H100+29) | R100: =IF(H100="","",IF(Q100="Done","Mastered",IF(M100<>"Done",L100,IF(O100<>"Done",N100,P100)))) | S100: =IF(H100="","Not started",IF(Q100="Done","Mastered",IF(OR(M100="Redo",O100="Redo",Q100="Redo"),"Redo",IF(R100<=TODAY(),"Re-solve due","In progress")))) -> Not started
...
